Traceback (most recent call last):
  File "/home/null/.local/lib/python3.11/site-packages/mysql/connector/connection_cext.py", line 365, in _open_connection
    self._cmysql.connect(**cnx_kwargs)
_mysql_connector.MySQLInterfaceError: Access denied for user 'root'@'localhost'

The above exception was the direct cause of the following exception:

Traceback (most recent call last):
  File "/home/null/Helix/python/webserver.py", line 6, in <module>
    auth_client = Auth()
                  ^^^^^^
  File "/home/null/Helix/python/backend/auth.py", line 17, in __init__
    self.db = Database()
              ^^^^^^^^^^
  File "/home/null/Helix/python/backend/db.py", line 6, in __init__
    self.connection = mysql.connector.connect(
                      ^^^^^^^^^^^^^^^^^^^^^^^^
  File "/home/null/.local/lib/python3.11/site-packages/mysql/connector/pooling.py", line 322, in connect
    return CMySQLConnection(*args, **kwargs)
           ^^^^^^^^^^^^^^^^^^^^^^^^^^^^^^^^^
  File "/home/null/.local/lib/python3.11/site-packages/mysql/connector/connection_cext.py", line 153, in __init__
    self.connect(**kwargs)
  File "/home/null/.local/lib/python3.11/site-packages/mysql/connector/abstracts.py", line 1529, in connect
    self._open_connection()
  File "/home/null/.local/lib/python3.11/site-packages/mysql/connector/connection_cext.py", line 370, in _open_connection
    raise get_mysql_exception(
mysql.connector.errors.ProgrammingError: 1698 (28000): Access denied for user 'root'@'localhost'
